<?xml version="1.0" encoding="UTF-8"?>
<!-- Generated by org.testng.reporters.JUnitReportReporter -->
<testsuite hostname="SHHQD0016" name="com.vipabc.test.login.Login" tests="9" failures="0" timestamp="24 Nov 2016 07:43:18 GMT" time="1.014" errors="1">
  <testcase name="login" time="0.103" classname="com.vipabc.test.login.Login"/>
  <testcase name="login" time="0.108" classname="com.vipabc.test.login.Login"/>
  <testcase name="login" time="0.108" classname="com.vipabc.test.login.Login">
    <error type="java.lang.AssertionError" message="expected [true] but found [false]">
      <![CDATA[java.lang.AssertionError: expected [true] but found [false]
	at org.testng.Assert.fail(Assert.java:94)
	at org.testng.Assert.failNotEquals(Assert.java:494)
	at org.testng.Assert.assertEquals(Assert.java:123)
	at org.testng.Assert.assertEquals(Assert.java:176)
	at org.testng.Assert.assertEquals(Assert.java:186)
	at com.vipabc.test.login.Login.login(Login.java:30)
	at sun.reflect.NativeMethodAccessorImpl.invoke0(Native Method)
	at sun.reflect.NativeMethodAccessorImpl.invoke(NativeMethodAccessorImpl.java:62)
	at sun.reflect.DelegatingMethodAccessorImpl.invoke(DelegatingMethodAccessorImpl.java:43)
	at java.lang.reflect.Method.invoke(Method.java:498)
	at org.testng.internal.MethodInvocationHelper.invokeMethod(MethodInvocationHelper.java:84)
	at org.testng.internal.Invoker.invokeMethod(Invoker.java:714)
	at org.testng.internal.Invoker.invokeTestMethod(Invoker.java:901)
	at org.testng.internal.Invoker.invokeTestMethods(Invoker.java:1231)
	at org.testng.internal.TestMethodWorker.invokeTestMethods(TestMethodWorker.java:127)
	at org.testng.internal.TestMethodWorker.run(TestMethodWorker.java:111)
	at org.testng.TestRunner.privateRun(TestRunner.java:767)
	at org.testng.TestRunner.run(TestRunner.java:617)
	at org.testng.SuiteRunner.runTest(SuiteRunner.java:348)
	at org.testng.SuiteRunner.runSequentially(SuiteRunner.java:343)
	at org.testng.SuiteRunner.privateRun(SuiteRunner.java:305)
	at org.testng.SuiteRunner.run(SuiteRunner.java:254)
	at org.testng.SuiteRunnerWorker.runSuite(SuiteRunnerWorker.java:52)
	at org.testng.SuiteRunnerWorker.run(SuiteRunnerWorker.java:86)
	at org.testng.TestNG.runSuitesSequentially(TestNG.java:1224)
	at org.testng.TestNG.runSuitesLocally(TestNG.java:1149)
	at org.testng.TestNG.run(TestNG.java:1057)
	at org.testng.remote.AbstractRemoteTestNG.run(AbstractRemoteTestNG.java:132)
	at org.testng.remote.RemoteTestNG.initAndRun(RemoteTestNG.java:236)
	at org.testng.remote.RemoteTestNG.main(RemoteTestNG.java:81)
]]>
    </error>
  </testcase> <!-- login -->
  <testcase name="login" time="0.096" classname="com.vipabc.test.login.Login"/>
  <testcase name="login" time="0.117" classname="com.vipabc.test.login.Login"/>
  <testcase name="login" time="0.154" classname="com.vipabc.test.login.Login"/>
  <testcase name="login" time="0.091" classname="com.vipabc.test.login.Login"/>
  <testcase name="login" time="0.117" classname="com.vipabc.test.login.Login"/>
  <testcase name="login" time="0.120" classname="com.vipabc.test.login.Login"/>
</testsuite> <!-- com.vipabc.test.login.Login -->
